<?xml version="1.0" ?>
<!-- =================================================================================== -->
<!-- |    This document was autogenerated by xacro from /home/sergio/ros3/KIT_Phantom_X_Pincher_ROS2/phantom_ws/src/phantomx_pincher_description/urdf/phantomx_pincher.urdf.xacro | -->
<!-- |    EDITING THIS FILE BY HAND IS NOT RECOMMENDED                                 | -->
<!-- =================================================================================== -->
<!-- URDF for PhantomX Pincher Robot Arm -->
<robot name="phantomx_pincher">
  <!-- ============================= -->
  <!-- ðŸŽ¨ Global Material Definitions -->
  <!-- ============================= -->
  <material name="black">
    <color rgba="0 0 0 1"/>
  </material>
  <material name="gray">
    <color rgba="0.5 0.5 0.5 1"/>
  </material>
  <material name="white">
    <color rgba="1 1 1 1"/>
  </material>
  <material name="yellow">
    <color rgba="1 1 0 1"/>
  </material>
  <material name="green">
    <color rgba="0 1 0 1"/>
  </material>
  <material name="red">
    <color rgba="1 0 0 1"/>
  </material>
  <material name="blue">
    <color rgba="0 0 1 1"/>
  </material>
  <material name="purple">
    <color rgba="0.5 0 0.5 1"/>
  </material>
  <!-- ============================= -->
  <!-- ðŸ§± Robot Geometry -->
  <!-- ============================= -->
  <link name="baseFija_link">
    <visual>
      <origin rpy="0 0 -1.5707963267948966" xyz="0.155 0 0.000"/>
      <geometry>
        <mesh filename="package://phantomx_pincher_description/meshes/STL/baseElementosFijos.stl" scale="0.001 0.001 0.001"/>
      </geometry>
      <material name="black"/>
    </visual>
    <collision>
      <origin rpy="0 0 -1.5707963267948966" xyz="0.155 0 0.0045"/>
      <geometry>
        <box size="0.360 0.554 0.009"/>
      </geometry>
      <material name="black"/>
    </collision>
  </link>
  <link name="caseBaseRobot_link">
    <visual>
      <origin rpy="3.141592653589793 0 1.5707963267948966" xyz="0 0 0"/>
      <geometry>
        <mesh filename="package://phantomx_pincher_description/meshes/STL/caseBaseRobot.stl" scale="0.001 0.001 0.001"/>
      </geometry>
      <material name="gray"/>
    </visual>
    <collision>
      <origin rpy="3.141592653589793 0 1.5707963267948966" xyz="0 0 -0.024"/>
      <geometry>
        <box size="0.066 0.074 0.048"/>
      </geometry>
      <material name="gray"/>
    </collision>
  </link>
  <joint name="base_caseRobot_joint" type="fixed">
    <parent link="baseFija_link"/>
    <child link="caseBaseRobot_link"/>
    <origin rpy="0 0 0" xyz="-0.01325 0 0.054"/>
  </joint>
  <link name="zonaRecoleccion_link">
    <visual>
      <origin rpy="3.141592653589793 0 0" xyz="0 0 0"/>
      <geometry>
        <mesh filename="package://phantomx_pincher_description/meshes/STL/zonaCircular146mm.stl" scale="0.001 0.001 0.001"/>
      </geometry>
      <material name="white"/>
    </visual>
    <collision>
      <origin rpy="3.141592653589793 0 0" xyz="0 0 -0.003"/>
      <geometry>
        <cylinder length="0.006" radius="0.073"/>
      </geometry>
      <material name="white"/>
    </collision>
  </link>
  <joint name="base_zonaRecoleccion_joint" type="fixed">
    <parent link="baseFija_link"/>
    <child link="zonaRecoleccion_link"/>
    <origin rpy="0 0 0" xyz="0.096 0 0.015"/>
  </joint>
  <link name="airpump_link">
    <visual>
      <origin rpy="1.5707963267948966 0 -1.5707963267948966" xyz="0 0 0"/>
      <geometry>
        <mesh filename="package://phantomx_pincher_description/meshes/STL/ensambleAirpump.stl" scale="0.001 0.001 0.001"/>
      </geometry>
      <material name="gray"/>
    </visual>
    <collision>
      <origin rpy="1.5707963267948966 0 -1.5707963267948966" xyz="-0.0647 0 0.014"/>
      <geometry>
        <box size="0.062 0.0405 0.067"/>
      </geometry>
      <material name="gray"/>
    </collision>
  </link>
  <joint name="base_airpump_joint" type="fixed">
    <parent link="baseFija_link"/>
    <child link="airpump_link"/>
    <origin rpy="0 0 0" xyz="0 0 0.009"/>
  </joint>
  <link name="manijaTrasera_link">
    <visual>
      <origin rpy="-1.5707963267948966 0 1.5707963267948966" xyz="0 0 0"/>
      <geometry>
        <mesh filename="package://phantomx_pincher_description/meshes/STL/manija.stl" scale="0.001 0.001 0.001"/>
      </geometry>
      <material name="gray"/>
    </visual>
    <collision>
      <origin rpy="-1.5707963267948966 0 1.5707963267948966" xyz="-0.010 0 0"/>
      <geometry>
        <box size="0.136 0.0505 0.020"/>
      </geometry>
      <material name="gray"/>
    </collision>
  </link>
  <joint name="base_manijaTrasera_joint" type="fixed">
    <parent link="baseFija_link"/>
    <child link="manijaTrasera_link"/>
    <origin rpy="0 0 0" xyz="-0.102 0 0.03425"/>
  </joint>
  <link name="manijaDelantera_link">
    <visual>
      <origin rpy="-1.5707963267948966 0 1.5707963267948966" xyz="0 0 0"/>
      <geometry>
        <mesh filename="package://phantomx_pincher_description/meshes/STL/manija.stl" scale="0.001 0.001 0.001"/>
      </geometry>
      <material name="gray"/>
    </visual>
    <collision>
      <origin rpy="-1.5707963267948966 0 1.5707963267948966" xyz="-0.010 0 0"/>
      <geometry>
        <box size="0.136 0.0505 0.020"/>
      </geometry>
      <material name="gray"/>
    </collision>
  </link>
  <joint name="base_manijaDelantera_joint" type="fixed">
    <parent link="baseFija_link"/>
    <child link="manijaDelantera_link"/>
    <origin rpy="0 0 0" xyz="0.432 0 0.03425"/>
  </joint>
  <link name="canecaLateralIzquierda_link">
    <visual>
      <origin rpy="0 0 -1.5707963267948966" xyz="0 0 0"/>
      <geometry>
        <mesh filename="package://phantomx_pincher_description/meshes/STL/canecaGrande.stl" scale="0.001 0.001 0.001"/>
      </geometry>
      <material name="red"/>
    </visual>
    <collision>
      <origin rpy="0 0 -1.5707963267948966" xyz="0 0 0"/>
      <geometry>
        <mesh filename="package://phantomx_pincher_description/meshes/STL/canecaGrande.stl" scale="0.001 0.001 0.001"/>
      </geometry>
      <material name="red"/>
    </collision>
  </link>
  <joint name="base_canecaLateralIzquierda_joint" type="fixed">
    <parent link="baseFija_link"/>
    <child link="canecaLateralIzquierda_link"/>
    <origin rpy="0 0 0" xyz="-0.0135 0.12775 0.016"/>
  </joint>
  <link name="canecaLateralDerecha_link">
    <visual>
      <origin rpy="0 0 1.5707963267948966" xyz="0 0 0"/>
      <geometry>
        <mesh filename="package://phantomx_pincher_description/meshes/STL/canecaGrande.stl" scale="0.001 0.001 0.001"/>
      </geometry>
      <material name="yellow"/>
    </visual>
    <collision>
      <origin rpy="0 0 1.5707963267948966" xyz="0 0 0"/>
      <geometry>
        <mesh filename="package://phantomx_pincher_description/meshes/STL/canecaGrande.stl" scale="0.001 0.001 0.001"/>
      </geometry>
      <material name="yellow"/>
    </collision>
  </link>
  <joint name="base_canecaLateralDerecha_joint" type="fixed">
    <parent link="baseFija_link"/>
    <child link="canecaLateralDerecha_link"/>
    <origin rpy="0 0 0" xyz="-0.0135 -0.12775 0.016"/>
  </joint>
  <link name="canecaFrontalDerecha_link">
    <visual>
      <origin rpy="0 0 2.696533694331239" xyz="0 0 0"/>
      <geometry>
        <mesh filename="package://phantomx_pincher_description/meshes/STL/canecaGrande.stl" scale="0.001 0.001 0.001"/>
      </geometry>
      <material name="green"/>
    </visual>
    <collision>
      <origin rpy="0 0 2.696533694331239" xyz="0 0 0"/>
      <geometry>
        <mesh filename="package://phantomx_pincher_description/meshes/STL/canecaGrande.stl" scale="0.001 0.001 0.001"/>
      </geometry>
      <material name="green"/>
    </collision>
  </link>
  <joint name="base_canecaFrontalDerecha_joint" type="fixed">
    <parent link="baseFija_link"/>
    <child link="canecaFrontalDerecha_link"/>
    <origin rpy="0 0 0" xyz="0.19397558339 -0.09252160722 0.016"/>
  </joint>
  <link name="canecaFrontalIzquierda_link">
    <visual>
      <origin rpy="0 0 3.586651612848347" xyz="0 0 0"/>
      <geometry>
        <mesh filename="package://phantomx_pincher_description/meshes/STL/canecaGrande.stl" scale="0.001 0.001 0.001"/>
      </geometry>
      <material name="blue"/>
    </visual>
    <collision>
      <origin rpy="0 0 3.586651612848347" xyz="0 0 0"/>
      <geometry>
        <mesh filename="package://phantomx_pincher_description/meshes/STL/canecaGrande.stl" scale="0.001 0.001 0.001"/>
      </geometry>
      <material name="blue"/>
    </collision>
  </link>
  <joint name="base_canecaFrontalIzquierda_joint" type="fixed">
    <parent link="baseFija_link"/>
    <child link="canecaFrontalIzquierda_link"/>
    <origin rpy="0 0 0" xyz="0.19397558339 0.09252160722 0.016"/>
  </joint>
  <!-- ============================= -->
  <!-- ðŸŒ Global Rotation Wrapper -->
  <!-- ============================= -->
  <link name="world_link"/>
  <joint name="world_to_base_joint" type="fixed">
    <parent link="world_link"/>
    <child link="baseFija_link"/>
    <origin rpy="0 0 0" xyz="0 0 0"/>
  </joint>
  <!-- 
Superior (normal)	0 0 0
Inferior (desde abajo)	${PI} 0 0
Frontal	0 -${PI/2} 0
Trasera	0 ${PI/2} 0
Lateral derecha	0 0 -${PI/2}
Lateral izquierda	0 0 ${PI/2}
  -->
  <!--            -->
  <!-- Parameters -->
  <!--            -->
  <!--       -->
  <!-- Robot -->
  <!--       -->
  <link name="phantomx_pincher_base_link">
  </link>
  <!-- Base link -> kit "world_link" -->
  <joint name="phantomx_pincher_base_link_joint" type="fixed">
    <parent link="phantomx_pincher_base_link"/>
    <!-- Root of the kit defined in kit.xacro -->
    <child link="world_link"/>
    <origin rpy="0 0 0" xyz="0 0 0"/>
  </joint>
  <!-- Kit -> Arm mounting joint -->
  <joint name="phantomx_pincher_kit_to_arm_base_joint" type="fixed">
    <!-- Parent: link from kit.xacro where the robot sits -->
    <parent link="caseBaseRobot_link"/>
    <!-- Child: base link of the PhantomX arm -->
    <child link="phantomx_pincher_arm_base_link"/>
    <!-- Pose of the arm base relative to the kit (tuned in original repo) -->
    <origin rpy="0 0 0" xyz="0.01325 0 0.016"/>
  </joint>
  <!-- Base link of the arm, which can be used to attach it to the rest of the world -->
  <link name="phantomx_pincher_arm_base_link"/>
  <joint name="phantomx_pincher_arm_shoulder_pan_servo_joint" type="fixed">
    <parent link="phantomx_pincher_arm_base_link"/>
    <child link="phantomx_pincher_arm_shoulder_pan_servo_link"/>
    <origin rpy="1.5707963267948966 0.0 1.5707963267948966" xyz="0.0 0.0 0.0"/>
  </joint>
  <link name="phantomx_pincher_arm_shoulder_pan_servo_link">
    <visual>
      <origin rpy="0.0 0.0 0.0" xyz="0.0 0.0 0.0"/>
      <geometry>
        <mesh filename="package://phantomx_pincher_description/meshes/visual/ax12.dae"/>
      </geometry>
    </visual>
    <collision>
      <origin rpy="0.0 0.0 0.0" xyz="0.0 0.0 -0.0135"/>
      <geometry>
        <box size="0.032 0.038 0.05"/>
      </geometry>
    </collision>
    <inertial>
      <origin rpy="0.0 0.0 0.0" xyz="-7.38454e-07 0.000422614 -0.0130296"/>
      <mass value="0.08139802400654242"/>
      <inertia ixx="2.3143627968295997e-05" ixy="-6.904875516785507e-10" ixz="-2.4208698077741694e-10" iyy="1.9936031209683584e-05" iyz="3.504110421945422e-07" izz="1.2576986445925398e-05"/>
    </inertial>
  </link>
  <gazebo reference="phantomx_pincher_arm_shoulder_pan_servo_link">
    <mu1 value="1.0"/>
    <mu2 value="1.0"/>
  </gazebo>
  <joint name="phantomx_pincher_arm_shoulder_pan_joint" type="revolute">
    <parent link="phantomx_pincher_arm_shoulder_pan_servo_link"/>
    <child link="phantomx_pincher_arm_shoulder_pan_link"/>
    <origin rpy="-1.5707963267948966 1.5707963267948966 3.141592653589793" xyz="0 0.019 0.0"/>
    <axis xyz="0.0 0.0 -1.0"/>
    <limit effort="30" lower="-2.6179938779914944" upper="2.6179938779914944" velocity="1.5707963267948966"/>
    <dynamics damping="1.4" friction="0.02"/>
  </joint>
  <gazebo reference="phantomx_pincher_arm_shoulder_pan_joint">
    <springStiffness value="0.0"/>
    <springReference value="0.0"/>
  </gazebo>
  <link name="phantomx_pincher_arm_shoulder_pan_link">
    <visual>
      <origin rpy="0.0 0.0 0.0" xyz="0.0 0.0 0.0"/>
      <geometry>
        <mesh filename="package://phantomx_pincher_description/meshes/visual/f3.dae"/>
      </geometry>
    </visual>
    <collision>
      <origin rpy="0.0 0.0 0.0" xyz="0.0 0.0 -0.0045"/>
      <geometry>
        <box size="0.025 0.038 0.009"/>
      </geometry>
    </collision>
    <inertial>
      <origin rpy="0.0 0.0 0.0" xyz="-1.72524e-06 4.83783e-07 -0.00240396"/>
      <mass value="0.006374458272892439"/>
      <inertia ixx="9.270000220058128e-07" ixy="-2.5814168895313843e-12" ixz="-2.4985237649917935e-10" iyy="4.018633414376187e-07" iyz="9.813034257837808e-12" izz="1.2864371800536346e-06"/>
    </inertial>
  </link>
  <gazebo reference="phantomx_pincher_arm_shoulder_pan_link">
    <mu1 value="1.0"/>
    <mu2 value="1.0"/>
  </gazebo>
  <joint name="phantomx_pincher_arm_shoulder_lift_servo_joint" type="fixed">
    <parent link="phantomx_pincher_arm_shoulder_pan_link"/>
    <child link="phantomx_pincher_arm_shoulder_lift_servo_link"/>
    <origin rpy="0.0 3.141592653589793 0.0" xyz="0.0 0.0 -0.035"/>
  </joint>
  <link name="phantomx_pincher_arm_shoulder_lift_servo_link">
    <visual>
      <origin rpy="0.0 0.0 0.0" xyz="0.0 0.0 0.0"/>
      <geometry>
        <mesh filename="package://phantomx_pincher_description/meshes/visual/ax12.dae"/>
      </geometry>
    </visual>
    <collision>
      <origin rpy="0.0 0.0 0.0" xyz="0.0 0.0 -0.0135"/>
      <geometry>
        <box size="0.032 0.038 0.05"/>
      </geometry>
    </collision>
    <inertial>
      <origin rpy="0.0 0.0 0.0" xyz="-7.38454e-07 0.000422614 -0.0130296"/>
      <mass value="0.08139802400654242"/>
      <inertia ixx="2.3143627968295997e-05" ixy="-6.904875516785507e-10" ixz="-2.4208698077741694e-10" iyy="1.9936031209683584e-05" iyz="3.504110421945422e-07" izz="1.2576986445925398e-05"/>
    </inertial>
  </link>
  <gazebo reference="phantomx_pincher_arm_shoulder_lift_servo_link">
    <mu1 value="1.0"/>
    <mu2 value="1.0"/>
  </gazebo>
  <joint name="phantomx_pincher_arm_shoulder_lift_joint" type="revolute">
    <parent link="phantomx_pincher_arm_shoulder_lift_servo_link"/>
    <child link="phantomx_pincher_arm_shoulder_lift_link"/>
    <origin rpy="0.0 0.0 0.0" xyz="0.0 0.0 0.0"/>
    <axis xyz="0.0 1.0 0.0"/>
    <limit effort="30" lower="-2.0943951023931953" upper="2.0943951023931953" velocity="1.5707963267948966"/>
    <dynamics damping="1.4" friction="0.02"/>
  </joint>
  <gazebo reference="phantomx_pincher_arm_shoulder_lift_joint">
    <springStiffness value="0.0"/>
    <springReference value="0.0"/>
  </gazebo>
  <link name="phantomx_pincher_arm_shoulder_lift_link">
    <visual>
      <origin rpy="0.0 0.0 0.0" xyz="0.0 0.0 0.0"/>
      <geometry>
        <mesh filename="package://phantomx_pincher_description/meshes/visual/f4.dae"/>
      </geometry>
    </visual>
    <collision>
      <origin rpy="0.0 0.0 0.0" xyz="0.0 0.0 0.0215"/>
      <geometry>
        <box size="0.028 0.0485 0.065"/>
      </geometry>
    </collision>
    <inertial>
      <origin rpy="0.0 0.0 0.0" xyz="-0.000589318 3.65417e-05 0.0288737"/>
      <mass value="0.025203193826508614"/>
      <inertia ixx="1.997638801949545e-05" ixy="9.66261623973993e-10" ixz="1.0343105915459652e-06" iyy="1.214970461462084e-05" iyz="-1.7113644679963033e-08" izz="1.1427207264696245e-05"/>
    </inertial>
  </link>
  <gazebo reference="phantomx_pincher_arm_shoulder_lift_link">
    <mu1 value="1.0"/>
    <mu2 value="1.0"/>
  </gazebo>
  <joint name="phantomx_pincher_arm_shoulder_F10_0_joint" type="fixed">
    <parent link="phantomx_pincher_arm_shoulder_lift_link"/>
    <child link="phantomx_pincher_arm_shoulder_F10_0_link"/>
    <origin rpy="0.0 0.0 0.0" xyz="0.0 0.0 0.0545"/>
  </joint>
  <link name="phantomx_pincher_arm_shoulder_F10_0_link">
    <visual>
      <origin rpy="0.0 0.0 0.0" xyz="0.0 0.0 0.0"/>
      <geometry>
        <mesh filename="package://phantomx_pincher_description/meshes/visual/f10.dae"/>
      </geometry>
    </visual>
    <collision>
      <origin rpy="0.0 0.0 0.0" xyz="0.0 0.0 0.0"/>
      <geometry>
        <box size="0.025 0.038 0.004"/>
      </geometry>
    </collision>
    <inertial>
      <origin rpy="0.0 0.0 0.0" xyz="-8.67784e-06 -8.79317e-07 0.000171599"/>
      <mass value="0.0035170756160130324"/>
      <inertia ixx="3.992017647723594e-07" ixy="-3.5246444817584626e-12" ixz="-9.729500575523489e-13" iyy="2.2036114209006905e-07" iyz="2.2872438374335695e-12" izz="6.123206341186544e-07"/>
    </inertial>
  </link>
  <gazebo reference="phantomx_pincher_arm_shoulder_F10_0_link">
    <mu1 value="1.0"/>
    <mu2 value="1.0"/>
  </gazebo>
  <joint name="phantomx_pincher_arm_shoulder_F10_1_joint" type="fixed">
    <parent link="phantomx_pincher_arm_shoulder_F10_0_link"/>
    <child link="phantomx_pincher_arm_shoulder_F10_1_link"/>
    <origin rpy="0.0 0.0 0.0" xyz="0.0 0.0 0.004"/>
  </joint>
  <link name="phantomx_pincher_arm_shoulder_F10_1_link">
    <visual>
      <origin rpy="0.0 0.0 0.0" xyz="0.0 0.0 0.0"/>
      <geometry>
        <mesh filename="package://phantomx_pincher_description/meshes/visual/f10.dae"/>
      </geometry>
    </visual>
    <collision>
      <origin rpy="0.0 0.0 0.0" xyz="0.0 0.0 0.0"/>
      <geometry>
        <box size="0.025 0.038 0.004"/>
      </geometry>
    </collision>
    <inertial>
      <origin rpy="0.0 0.0 0.0" xyz="-8.67784e-06 -8.79317e-07 0.000171599"/>
      <mass value="0.0035170756160130324"/>
      <inertia ixx="3.992017647723594e-07" ixy="-3.5246444817584626e-12" ixz="-9.729500575523489e-13" iyy="2.2036114209006905e-07" iyz="2.2872438374335695e-12" izz="6.123206341186544e-07"/>
    </inertial>
  </link>
  <gazebo reference="phantomx_pincher_arm_shoulder_F10_1_link">
    <mu1 value="1.0"/>
    <mu2 value="1.0"/>
  </gazebo>
  <joint name="phantomx_pincher_arm_shoulder_F10_2_joint" type="fixed">
    <parent link="phantomx_pincher_arm_shoulder_F10_1_link"/>
    <child link="phantomx_pincher_arm_shoulder_F10_2_link"/>
    <origin rpy="0.0 0.0 0.0" xyz="0.0 0.0 0.004"/>
  </joint>
  <link name="phantomx_pincher_arm_shoulder_F10_2_link">
    <visual>
      <origin rpy="0.0 0.0 0.0" xyz="0.0 0.0 0.0"/>
      <geometry>
        <mesh filename="package://phantomx_pincher_description/meshes/visual/f10.dae"/>
      </geometry>
    </visual>
    <collision>
      <origin rpy="0.0 0.0 0.0" xyz="0.0 0.0 0.0"/>
      <geometry>
        <box size="0.025 0.038 0.004"/>
      </geometry>
    </collision>
    <inertial>
      <origin rpy="0.0 0.0 0.0" xyz="-8.67784e-06 -8.79317e-07 0.000171599"/>
      <mass value="0.0035170756160130324"/>
      <inertia ixx="3.992017647723594e-07" ixy="-3.5246444817584626e-12" ixz="-9.729500575523489e-13" iyy="2.2036114209006905e-07" iyz="2.2872438374335695e-12" izz="6.123206341186544e-07"/>
    </inertial>
  </link>
  <gazebo reference="phantomx_pincher_arm_shoulder_F10_2_link">
    <mu1 value="1.0"/>
    <mu2 value="1.0"/>
  </gazebo>
  <joint name="phantomx_pincher_arm_shoulder_F3_0_joint" type="fixed">
    <parent link="phantomx_pincher_arm_shoulder_F10_2_link"/>
    <child link="phantomx_pincher_arm_shoulder_F3_0_link"/>
    <origin rpy="0.0 3.141592653589793 0.0" xyz="0.0 0.0 0.002"/>
  </joint>
  <link name="phantomx_pincher_arm_shoulder_F3_0_link">
    <visual>
      <origin rpy="0.0 0.0 0.0" xyz="0.0 0.0 0.0"/>
      <geometry>
        <mesh filename="package://phantomx_pincher_description/meshes/visual/f3.dae"/>
      </geometry>
    </visual>
    <collision>
      <origin rpy="0.0 0.0 0.0" xyz="0.0 0.0 -0.0045"/>
      <geometry>
        <box size="0.025 0.038 0.009"/>
      </geometry>
    </collision>
    <inertial>
      <origin rpy="0.0 0.0 0.0" xyz="-1.72524e-06 4.83783e-07 -0.00240396"/>
      <mass value="0.006374458272892439"/>
      <inertia ixx="9.270000220058128e-07" ixy="-2.5814168895313843e-12" ixz="-2.4985237649917935e-10" iyy="4.018633414376187e-07" iyz="9.813034257837808e-12" izz="1.2864371800536346e-06"/>
    </inertial>
  </link>
  <gazebo reference="phantomx_pincher_arm_shoulder_F3_0_link">
    <mu1 value="1.0"/>
    <mu2 value="1.0"/>
  </gazebo>
  <joint name="phantomx_pincher_arm_elbow_flex_servo_joint" type="fixed">
    <parent link="phantomx_pincher_arm_shoulder_F3_0_link"/>
    <child link="phantomx_pincher_arm_elbow_flex_servo_link"/>
    <origin rpy="0.0 3.141592653589793 0.0" xyz="0.0 0.0 -0.035"/>
  </joint>
  <link name="phantomx_pincher_arm_elbow_flex_servo_link">
    <visual>
      <origin rpy="0.0 0.0 0.0" xyz="0.0 0.0 0.0"/>
      <geometry>
        <mesh filename="package://phantomx_pincher_description/meshes/visual/ax12.dae"/>
      </geometry>
    </visual>
    <collision>
      <origin rpy="0.0 0.0 0.0" xyz="0.0 0.0 -0.0135"/>
      <geometry>
        <box size="0.032 0.038 0.05"/>
      </geometry>
    </collision>
    <inertial>
      <origin rpy="0.0 0.0 0.0" xyz="-7.38454e-07 0.000422614 -0.0130296"/>
      <mass value="0.08139802400654242"/>
      <inertia ixx="2.3143627968295997e-05" ixy="-6.904875516785507e-10" ixz="-2.4208698077741694e-10" iyy="1.9936031209683584e-05" iyz="3.504110421945422e-07" izz="1.2576986445925398e-05"/>
    </inertial>
  </link>
  <gazebo reference="phantomx_pincher_arm_elbow_flex_servo_link">
    <mu1 value="1.0"/>
    <mu2 value="1.0"/>
  </gazebo>
  <joint name="phantomx_pincher_arm_elbow_flex_joint" type="revolute">
    <parent link="phantomx_pincher_arm_elbow_flex_servo_link"/>
    <child link="phantomx_pincher_arm_elbow_flex_link"/>
    <origin rpy="0.0 0.0 0.0" xyz="0.0 0.0 0.0"/>
    <axis xyz="0.0 1.0 0.0"/>
    <limit effort="30" lower="-2.426007660272118" upper="2.426007660272118" velocity="1.5707963267948966"/>
    <dynamics damping="1.4" friction="0.02"/>
  </joint>
  <gazebo reference="phantomx_pincher_arm_elbow_flex_joint">
    <springStiffness value="0.0"/>
    <springReference value="0.0"/>
  </gazebo>
  <link name="phantomx_pincher_arm_elbow_flex_link">
    <visual>
      <origin rpy="0.0 0.0 0.0" xyz="0.0 0.0 0.0"/>
      <geometry>
        <mesh filename="package://phantomx_pincher_description/meshes/visual/f4.dae"/>
      </geometry>
    </visual>
    <collision>
      <origin rpy="0.0 0.0 0.0" xyz="0.0 0.0 0.0215"/>
      <geometry>
        <box size="0.028 0.0485 0.065"/>
      </geometry>
    </collision>
    <inertial>
      <origin rpy="0.0 0.0 0.0" xyz="-0.000589318 3.65417e-05 0.0288737"/>
      <mass value="0.025203193826508614"/>
      <inertia ixx="1.997638801949545e-05" ixy="9.66261623973993e-10" ixz="1.0343105915459652e-06" iyy="1.214970461462084e-05" iyz="-1.7113644679963033e-08" izz="1.1427207264696245e-05"/>
    </inertial>
  </link>
  <gazebo reference="phantomx_pincher_arm_elbow_flex_link">
    <mu1 value="1.0"/>
    <mu2 value="1.0"/>
  </gazebo>
  <joint name="phantomx_pincher_arm_elbow_F10_0_joint" type="fixed">
    <parent link="phantomx_pincher_arm_elbow_flex_link"/>
    <child link="phantomx_pincher_arm_elbow_F10_0_link"/>
    <origin rpy="0.0 0.0 0.0" xyz="0.0 0.0 0.0545"/>
  </joint>
  <link name="phantomx_pincher_arm_elbow_F10_0_link">
    <visual>
      <origin rpy="0.0 0.0 0.0" xyz="0.0 0.0 0.0"/>
      <geometry>
        <mesh filename="package://phantomx_pincher_description/meshes/visual/f10.dae"/>
      </geometry>
    </visual>
    <collision>
      <origin rpy="0.0 0.0 0.0" xyz="0.0 0.0 0.0"/>
      <geometry>
        <box size="0.025 0.038 0.004"/>
      </geometry>
    </collision>
    <inertial>
      <origin rpy="0.0 0.0 0.0" xyz="-8.67784e-06 -8.79317e-07 0.000171599"/>
      <mass value="0.0035170756160130324"/>
      <inertia ixx="3.992017647723594e-07" ixy="-3.5246444817584626e-12" ixz="-9.729500575523489e-13" iyy="2.2036114209006905e-07" iyz="2.2872438374335695e-12" izz="6.123206341186544e-07"/>
    </inertial>
  </link>
  <gazebo reference="phantomx_pincher_arm_elbow_F10_0_link">
    <mu1 value="1.0"/>
    <mu2 value="1.0"/>
  </gazebo>
  <joint name="phantomx_pincher_arm_elbow_F10_1_joint" type="fixed">
    <parent link="phantomx_pincher_arm_elbow_F10_0_link"/>
    <child link="phantomx_pincher_arm_elbow_F10_1_link"/>
    <origin rpy="0.0 0.0 0.0" xyz="0.0 0.0 0.004"/>
  </joint>
  <link name="phantomx_pincher_arm_elbow_F10_1_link">
    <visual>
      <origin rpy="0.0 0.0 0.0" xyz="0.0 0.0 0.0"/>
      <geometry>
        <mesh filename="package://phantomx_pincher_description/meshes/visual/f10.dae"/>
      </geometry>
    </visual>
    <collision>
      <origin rpy="0.0 0.0 0.0" xyz="0.0 0.0 0.0"/>
      <geometry>
        <box size="0.025 0.038 0.004"/>
      </geometry>
    </collision>
    <inertial>
      <origin rpy="0.0 0.0 0.0" xyz="-8.67784e-06 -8.79317e-07 0.000171599"/>
      <mass value="0.0035170756160130324"/>
      <inertia ixx="3.992017647723594e-07" ixy="-3.5246444817584626e-12" ixz="-9.729500575523489e-13" iyy="2.2036114209006905e-07" iyz="2.2872438374335695e-12" izz="6.123206341186544e-07"/>
    </inertial>
  </link>
  <gazebo reference="phantomx_pincher_arm_elbow_F10_1_link">
    <mu1 value="1.0"/>
    <mu2 value="1.0"/>
  </gazebo>
  <joint name="phantomx_pincher_arm_elbow_F10_2_joint" type="fixed">
    <parent link="phantomx_pincher_arm_elbow_F10_1_link"/>
    <child link="phantomx_pincher_arm_elbow_F10_2_link"/>
    <origin rpy="0.0 0.0 0.0" xyz="0.0 0.0 0.004"/>
  </joint>
  <link name="phantomx_pincher_arm_elbow_F10_2_link">
    <visual>
      <origin rpy="0.0 0.0 0.0" xyz="0.0 0.0 0.0"/>
      <geometry>
        <mesh filename="package://phantomx_pincher_description/meshes/visual/f10.dae"/>
      </geometry>
    </visual>
    <collision>
      <origin rpy="0.0 0.0 0.0" xyz="0.0 0.0 0.0"/>
      <geometry>
        <box size="0.025 0.038 0.004"/>
      </geometry>
    </collision>
    <inertial>
      <origin rpy="0.0 0.0 0.0" xyz="-8.67784e-06 -8.79317e-07 0.000171599"/>
      <mass value="0.0035170756160130324"/>
      <inertia ixx="3.992017647723594e-07" ixy="-3.5246444817584626e-12" ixz="-9.729500575523489e-13" iyy="2.2036114209006905e-07" iyz="2.2872438374335695e-12" izz="6.123206341186544e-07"/>
    </inertial>
  </link>
  <gazebo reference="phantomx_pincher_arm_elbow_F10_2_link">
    <mu1 value="1.0"/>
    <mu2 value="1.0"/>
  </gazebo>
  <joint name="phantomx_pincher_arm_elbow_F3_0_joint" type="fixed">
    <parent link="phantomx_pincher_arm_elbow_F10_2_link"/>
    <child link="phantomx_pincher_arm_elbow_F3_0_link"/>
    <origin rpy="0.0 3.141592653589793 0.0" xyz="0.0 0.0 0.002"/>
  </joint>
  <link name="phantomx_pincher_arm_elbow_F3_0_link">
    <visual>
      <origin rpy="0.0 0.0 0.0" xyz="0.0 0.0 0.0"/>
      <geometry>
        <mesh filename="package://phantomx_pincher_description/meshes/visual/f3.dae"/>
      </geometry>
    </visual>
    <collision>
      <origin rpy="0.0 0.0 0.0" xyz="0.0 0.0 -0.0045"/>
      <geometry>
        <box size="0.025 0.038 0.009"/>
      </geometry>
    </collision>
    <inertial>
      <origin rpy="0.0 0.0 0.0" xyz="-1.72524e-06 4.83783e-07 -0.00240396"/>
      <mass value="0.006374458272892439"/>
      <inertia ixx="9.270000220058128e-07" ixy="-2.5814168895313843e-12" ixz="-2.4985237649917935e-10" iyy="4.018633414376187e-07" iyz="9.813034257837808e-12" izz="1.2864371800536346e-06"/>
    </inertial>
  </link>
  <gazebo reference="phantomx_pincher_arm_elbow_F3_0_link">
    <mu1 value="1.0"/>
    <mu2 value="1.0"/>
  </gazebo>
  <joint name="phantomx_pincher_arm_wrist_flex_servo_joint" type="fixed">
    <parent link="phantomx_pincher_arm_elbow_F3_0_link"/>
    <child link="phantomx_pincher_arm_wrist_flex_servo_link"/>
    <origin rpy="0.0 3.141592653589793 0.0" xyz="0.0 0.0 -0.035"/>
  </joint>
  <link name="phantomx_pincher_arm_wrist_flex_servo_link">
    <visual>
      <origin rpy="0.0 0.0 0.0" xyz="0.0 0.0 0.0"/>
      <geometry>
        <mesh filename="package://phantomx_pincher_description/meshes/visual/ax12.dae"/>
      </geometry>
    </visual>
    <collision>
      <origin rpy="0.0 0.0 0.0" xyz="0.0 0.0 -0.0135"/>
      <geometry>
        <box size="0.032 0.038 0.05"/>
      </geometry>
    </collision>
    <inertial>
      <origin rpy="0.0 0.0 0.0" xyz="-7.38454e-07 0.000422614 -0.0130296"/>
      <mass value="0.08139802400654242"/>
      <inertia ixx="2.3143627968295997e-05" ixy="-6.904875516785507e-10" ixz="-2.4208698077741694e-10" iyy="1.9936031209683584e-05" iyz="3.504110421945422e-07" izz="1.2576986445925398e-05"/>
    </inertial>
  </link>
  <gazebo reference="phantomx_pincher_arm_wrist_flex_servo_link">
    <mu1 value="1.0"/>
    <mu2 value="1.0"/>
  </gazebo>
  <joint name="phantomx_pincher_arm_wrist_flex_joint" type="revolute">
    <parent link="phantomx_pincher_arm_wrist_flex_servo_link"/>
    <child link="phantomx_pincher_arm_wrist_flex_link"/>
    <origin rpy="0.0 0.0 0.0" xyz="0.0 0.0 0.0"/>
    <axis xyz="0.0 1.0 0.0"/>
    <limit effort="30" lower="-1.710422666954443" upper="1.7976891295541593" velocity="1.5707963267948966"/>
    <dynamics damping="1.4" friction="0.02"/>
  </joint>
  <gazebo reference="phantomx_pincher_arm_wrist_flex_joint">
    <springStiffness value="0.0"/>
    <springReference value="0.0"/>
  </gazebo>
  <link name="phantomx_pincher_arm_wrist_flex_link">
    <visual>
      <origin rpy="0.0 0.0 0.0" xyz="0.0 0.0 0.0"/>
      <geometry>
        <mesh filename="package://phantomx_pincher_description/meshes/visual/f2.dae"/>
      </geometry>
    </visual>
    <collision>
      <origin rpy="0.0 0.0 0.0" xyz="0.0 0.0 0.00775"/>
      <geometry>
        <box size="0.025 0.0485 0.0375"/>
      </geometry>
    </collision>
    <inertial>
      <origin rpy="0.0 0.0 0.0" xyz="1.83625e-06 4.41782e-08 0.0154045"/>
      <mass value="0.014479017200129543"/>
      <inertia ixx="6.472388590001224e-06" ixy="-1.892671596204799e-12" ixz="-3.0007457063740617e-10" iyy="2.498962550910956e-06" iyz="-2.3584142968316667e-12" izz="5.6994603934534456e-06"/>
    </inertial>
  </link>
  <gazebo reference="phantomx_pincher_arm_wrist_flex_link">
    <mu1 value="1.0"/>
    <mu2 value="1.0"/>
  </gazebo>
  <joint name="phantomx_pincher_arm_wrist_F3_0_joint" type="fixed">
    <parent link="phantomx_pincher_arm_wrist_flex_link"/>
    <child link="phantomx_pincher_arm_wrist_F3_0_link"/>
    <origin rpy="0 3.141592653589793 -3.141592653589793" xyz="0.0 0.0 0.0265"/>
  </joint>
  <link name="phantomx_pincher_arm_wrist_F3_0_link">
    <visual>
      <origin rpy="0.0 0.0 0.0" xyz="0.0 0.0 0.0"/>
      <geometry>
        <mesh filename="package://phantomx_pincher_description/meshes/visual/f3.dae"/>
      </geometry>
    </visual>
    <collision>
      <origin rpy="0.0 0.0 0.0" xyz="0.0 0.0 -0.0045"/>
      <geometry>
        <box size="0.025 0.038 0.009"/>
      </geometry>
    </collision>
    <inertial>
      <origin rpy="0.0 0.0 0.0" xyz="-1.72524e-06 4.83783e-07 -0.00240396"/>
      <mass value="0.006374458272892439"/>
      <inertia ixx="9.270000220058128e-07" ixy="-2.5814168895313843e-12" ixz="-2.4985237649917935e-10" iyy="4.018633414376187e-07" iyz="9.813034257837808e-12" izz="1.2864371800536346e-06"/>
    </inertial>
  </link>
  <gazebo reference="phantomx_pincher_arm_wrist_F3_0_link">
    <mu1 value="1.0"/>
    <mu2 value="1.0"/>
  </gazebo>
  <joint name="phantomx_pincher_gripper_servo_joint" type="fixed">
    <parent link="phantomx_pincher_arm_wrist_F3_0_link"/>
    <child link="phantomx_pincher_gripper_servo_link"/>
    <origin rpy="1.5707963267948966 3.141592653589793 1.5707963267948966" xyz="0.0 0.0 -0.019"/>
  </joint>
  <link name="phantomx_pincher_gripper_servo_link">
    <visual>
      <origin rpy="0.0 0.0 0.0" xyz="0.0 0.0 0.0"/>
      <geometry>
        <mesh filename="package://phantomx_pincher_description/meshes/visual/ax12.dae"/>
      </geometry>
    </visual>
    <collision>
      <origin rpy="0.0 0.0 0.0" xyz="0.0 0.0 -0.0135"/>
      <geometry>
        <box size="0.032 0.038 0.05"/>
      </geometry>
    </collision>
    <inertial>
      <origin rpy="0.0 0.0 0.0" xyz="-7.38454e-07 0.000422614 -0.0130296"/>
      <mass value="0.08139802400654242"/>
      <inertia ixx="2.3143627968295997e-05" ixy="-6.904875516785507e-10" ixz="-2.4208698077741694e-10" iyy="1.9936031209683584e-05" iyz="3.504110421945422e-07" izz="1.2576986445925398e-05"/>
    </inertial>
  </link>
  <gazebo reference="phantomx_pincher_gripper_servo_link">
    <mu1 value="1.0"/>
    <mu2 value="1.0"/>
  </gazebo>
  <joint name="phantomx_pincher_gripper_finger_base_joint" type="fixed">
    <parent link="phantomx_pincher_gripper_servo_link"/>
    <child link="phantomx_pincher_gripper_finger_base_link"/>
    <origin rpy="3.141592653589793 0.0 1.5707963267948966" xyz="0 0.019 0.0"/>
  </joint>
  <link name="phantomx_pincher_gripper_finger_base_link">
    <visual>
      <origin rpy="0.0 0.0 0.0" xyz="0.0 0.0 0.0"/>
      <geometry>
        <mesh filename="package://phantomx_pincher_description/meshes/visual/gripper_base.dae"/>
      </geometry>
    </visual>
    <collision>
      <origin rpy="0.0 0.0 0.0" xyz="0.0 0.0 0.0"/>
      <geometry>
        <box size="0.002 0.075 0.040"/>
      </geometry>
    </collision>
    <inertial>
      <origin rpy="0.0 0.0 0.0" xyz="0 2.98023e-08 0"/>
      <mass value="0.011837674839899828"/>
      <inertia ixx="7.127260849628046e-06" ixy="3.400011875409145e-24" ixz="-0.0" iyy="1.5822994239366863e-06" iyz="-0.0" izz="5.5528530038746866e-06"/>
    </inertial>
  </link>
  <gazebo reference="phantomx_pincher_gripper_finger_base_link">
    <mu1 value="1.0"/>
    <mu2 value="1.0"/>
  </gazebo>
  <joint name="phantomx_pincher_gripper_finger1_joint" type="prismatic">
    <parent link="phantomx_pincher_gripper_finger_base_link"/>
    <child link="phantomx_pincher_gripper_finger1_link"/>
    <origin rpy="1.5707963267948966 0.0 1.5707963267948966" xyz="0.019 0.0115 0.0"/>
    <axis xyz="1.0 0.0 0.0"/>
    <limit effort="30" lower="0.001" upper="0.0158" velocity="0.01"/>
    <dynamics damping="1.8" friction="0.06"/>
  </joint>
  <gazebo reference="phantomx_pincher_gripper_finger1_joint">
    <springStiffness value="0.0"/>
    <springReference value="0.0"/>
  </gazebo>
  <link name="phantomx_pincher_gripper_finger1_link">
    <visual>
      <origin rpy="0.0 0.0 0.0" xyz="0.0 0.0 0.0"/>
      <geometry>
        <mesh filename="package://phantomx_pincher_description/meshes/visual/finger.dae"/>
      </geometry>
    </visual>
    <collision>
      <origin rpy="0.0 0.0 0.0" xyz="0.0 0.0 0.0"/>
      <geometry>
        <mesh filename="package://phantomx_pincher_description/meshes/collision/finger.stl"/>
      </geometry>
    </collision>
    <inertial>
      <origin rpy="0.0 0.0 0.0" xyz="-0.00607194 -4.42132e-19 -0.00471261"/>
      <mass value="0.009843256743296712"/>
      <inertia ixx="1.8229100836948666e-06" ixy="-2.797502899373518e-23" ixz="3.498974201392864e-07" iyy="1.595545910676557e-06" iyz="4.770944797128244e-23" izz="1.0262210845211422e-06"/>
    </inertial>
  </link>
  <gazebo reference="phantomx_pincher_gripper_finger1_link">
    <mu1 value="1.0"/>
    <mu2 value="1.0"/>
  </gazebo>
  <joint name="phantomx_pincher_gripper_finger2_joint" type="prismatic">
    <parent link="phantomx_pincher_gripper_finger_base_link"/>
    <child link="phantomx_pincher_gripper_finger2_link"/>
    <origin rpy="1.5707963267948966 3.141592653589793 1.5707963267948966" xyz="0.019 -0.0115 0.0"/>
    <axis xyz="1.0 0.0 0.0"/>
    <limit effort="30" lower="0.001" upper="0.0158" velocity="0.01"/>
    <dynamics damping="1.8" friction="0.06"/>
  </joint>
  <gazebo reference="phantomx_pincher_gripper_finger2_joint">
    <springStiffness value="0.0"/>
    <springReference value="0.0"/>
  </gazebo>
  <link name="phantomx_pincher_gripper_finger2_link">
    <visual>
      <origin rpy="0.0 0.0 0.0" xyz="0.0 0.0 0.0"/>
      <geometry>
        <mesh filename="package://phantomx_pincher_description/meshes/visual/finger.dae"/>
      </geometry>
    </visual>
    <collision>
      <origin rpy="0.0 0.0 0.0" xyz="0.0 0.0 0.0"/>
      <geometry>
        <mesh filename="package://phantomx_pincher_description/meshes/collision/finger.stl"/>
      </geometry>
    </collision>
    <inertial>
      <origin rpy="0.0 0.0 0.0" xyz="-0.00607194 -4.42132e-19 -0.00471261"/>
      <mass value="0.009843256743296712"/>
      <inertia ixx="1.8229100836948666e-06" ixy="-2.797502899373518e-23" ixz="3.498974201392864e-07" iyy="1.595545910676557e-06" iyz="4.770944797128244e-23" izz="1.0262210845211422e-06"/>
    </inertial>
  </link>
  <gazebo reference="phantomx_pincher_gripper_finger2_link">
    <mu1 value="1.0"/>
    <mu2 value="1.0"/>
  </gazebo>
  <link name="phantomx_pincher_end_effector">
  </link>
  <joint name="phantomx_pincher_end_effector_virtual_joint" type="fixed">
    <parent link="phantomx_pincher_gripper_finger_base_link"/>
    <child link="phantomx_pincher_end_effector"/>
    <origin rpy="1.5707963267948966 -1.5707963267948966 1.5707963267948966" xyz="0.019 0.0 0.0"/>
  </joint>
  <ros2_control name="phantomx_pincher_ros2_control_system" type="system">
    <hardware>
      <plugin>fake_components/GenericSystem</plugin>
    </hardware>
    <joint name="phantomx_pincher_arm_shoulder_pan_joint">
      <param name="initial_position">0.0</param>
      <command_interface name="position"/>
      <state_interface name="position"/>
      <state_interface name="velocity"/>
      <state_interface name="effort"/>
    </joint>
    <joint name="phantomx_pincher_arm_shoulder_lift_joint">
      <param name="initial_position">0.0</param>
      <command_interface name="position"/>
      <state_interface name="position"/>
      <state_interface name="velocity"/>
      <state_interface name="effort"/>
    </joint>
    <joint name="phantomx_pincher_arm_elbow_flex_joint">
      <param name="initial_position">0.0</param>
      <command_interface name="position"/>
      <state_interface name="position"/>
      <state_interface name="velocity"/>
      <state_interface name="effort"/>
    </joint>
    <joint name="phantomx_pincher_arm_wrist_flex_joint">
      <param name="initial_position">0.0</param>
      <command_interface name="position"/>
      <state_interface name="position"/>
      <state_interface name="velocity"/>
      <state_interface name="effort"/>
    </joint>
    <joint name="phantomx_pincher_gripper_finger1_joint">
      <param name="initial_position">0.001</param>
      <command_interface name="position"/>
      <state_interface name="position"/>
      <state_interface name="velocity"/>
      <state_interface name="effort"/>
    </joint>
    <joint name="phantomx_pincher_gripper_finger2_joint">
      <param name="initial_position">0.001</param>
      <command_interface name="position"/>
      <state_interface name="position"/>
      <state_interface name="velocity"/>
      <state_interface name="effort"/>
    </joint>
  </ros2_control>
  <!-- Example environment / mounting macros (kept commented out) -->
  <!--
  <xacro:task_board
      prefix="$(arg prefix)"
      child="task_board_mount_link"
      collision="$(arg collision)"
      gazebo_preserve_fixed_joint="$(arg gazebo_preserve_fixed_joint)"/>

  <xacro:task_board_mount
      prefix="$(arg prefix)"
      child="base_mount_link"
      collision="$(arg collision)"
      gazebo_preserve_fixed_joint="$(arg gazebo_preserve_fixed_joint)"/>

  <xacro:base_mount
      prefix="$(arg prefix)"
      child="arm_base_link"
      collision="$(arg collision)"
      gazebo_preserve_fixed_joint="$(arg gazebo_preserve_fixed_joint)"/>
  -->
  <!-- Gazebo - ROS 2 control (Ignition) 
  <xacro:if value="$(arg ros2_control)">
    <xacro:if value="${'ign' in '$(arg ros2_control_plugin)' or 'gz' in '$(arg ros2_control_plugin)'}">
      <xacro:ign_ros2_control controller_parameters="$(arg ros2_controller_parameters)"/>
    </xacro:if>
  </xacro:if>
  -->
</robot>
